Workbook
Name Slicer_Category: #N/A
Name Slicer_Sales_Channel: #N/A
Name Slicer_Status: #N/A
Name Slicer_T212: #N/A

Sheet Pivot
A3: Row Labels | B3: Sum of Net_Sales
A4: Camera | B4: 78120
A5: Laptop | B5: 95680
A6: Monitor | B6: 41216
A7: Printer | B7: 66600
A8: Projector | B8: 85560
A9: Refrigerator | B9: 72380
A10: Smartphone | B10: 133950
A11: Smartwatch | B11: 40320
A12: Tablet | B12: 77440
A13: Washing Machine | B13: 57960
A14: Grand Total | B14: 749226
A25: Sum of Net_Sales | B25: Column Labels
A26: Row Labels | B26: Cancelled | C26: Completed | D26: Pending | E26: Refunded | F26: Grand Total
A27: East | B27: 0 | C27: 363756 | E27: 28560 | F27: 392316
A28: North | C28: 504715.9 | F28: 504715.9
A29: South | C29: 128509.4 | D29: 45560 | E29: 15360 | F29: 189429.4
A30: West | B30: 12960 | C30: 458650.5 | D30: 44592 | F30: 516202.5
A31: Grand Total | B31: 12960 | C31: 1455631.8 | D31: 90152 | E31: 43920 | F31: 1602663.8
A34: COMPLETED TRANSACTIONS
A35: =COUNTIF(Transactions!L:L,"Completed") -> 67
A48: =SUM(Transactions!P2:P77)/COUNTA(Transactions!A2:A77) -> 20977.155

Sheet T34
A3: Row Labels | B3: Sum of Net_Sales
A4: April | B4: 248214.9
A5: February | B5: 243171.5
A6: January | B6: 529893.4
A7: March | B7: 463243.2
A8: May | B8: 118140.8
A9: Grand Total | B9: 1602663.8

Sheet Transactions
A1: Transaction_ID | B1: Date | C1: Region | D1: Sales_Channel | E1: Customer_Name | F1: Category | G1: Product | H1: Quantity | I1: Unit_Price_INR | J1: Discount_Rate | K1: Payment_Method | L1: Status | M1: Sales_Rep_ID | N1: Gross sales | O1: Discount_Amount | P1: Net_Sales | Q1: Transaction_month | R1: Transaction_Flag | S1: classification_netsales | T1: AND | U1: OR | V1: iferror | W1: T21 | X1: T22 | Y1: Year | Z1: Month | AA1: id | AB1: Region_category
A2: TXN1001 | B2: 46025 | C2: North | D2: Retail | E2: Asha Stores | F2: Electronics | G2: Laptop | H2: 2 | I2: 52000 | J2: 0.08 | K2: UPI | L2: Completed | M2: EMP01 | N2: =Table1[[#This Row],[Quantity]]*Table1[[#This Row],[Unit_Price_INR]] -> 104000 | O2: =Table1[[#This Row],[Gross sales]]*Table1[[#This Row],[Discount_Rate]] -> 8320 | P2: =Table1[[#This Row],[Gross sales]]-Table1[[#This Row],[Discount_Amount]] -> 95680 | Q2: =TEXT(Table1[[#This Row],[Date]],"mmmm") -> January | R2: =IF(OR(Table1[[#This Row],[Status]]="Pending",Table1[[#This Row],[Status]]="Refunded"),"Review","OK") -> OK | S2: =IF(Table1[[#This Row],[Net_Sales]]>25000,"Hgh",IF(Table1[[#This Row],[Net_Sales]]>10000,"Medium","Low")) -> Hgh | T2: =AND(Table1[[#This Row],[Quantity]]>=5,Table1[[#This Row],[Discount_Rate]]>=10%) -> FALSE | U2: =OR(Table1[[#This Row],[Payment_Method]]="UPI",Table1[[#This Row],[Payment_Method]]="Cash") -> TRUE | V2: =IFERROR(Table1[[#This Row],[Net_Sales]]/Table1[[#This Row],[Quantity]],"ERROR") -> 47840 | W2: =PROPER(TRIM(Table1[[#This Row],[Customer_Name]])) -> Asha Stores | X2: =PROPER(TRIM(Table1[[#This Row],[Region]])) -> North | Y2: =YEAR(Table1[[#This Row],[Date]]) -> 2026 | Z2: =MONTH(Table1[[#This Row],[Date]]) -> 1 | AA2: =MID(Table1[[#This Row],[Transaction_ID]],4,7) -> 1001 | AB2: =_xlfn.CONCAT(Table1[[#This Row],[Region]],"-",Table1[[#This Row],[Category]]) -> North-Electronics
A3: TXN1002 | B3: 46026 | C3: South | D3: Online | E3: Bright Mart | F3: Home | G3: Mixer Grinder | H3: 3 | I3: 4200 | J3: 0.05 | K3: Card | L3: Completed | M3: EMP03 | N3: =Table1[[#This Row],[Quantity]]*Table1[[#This Row],[Unit_Price_INR]] -> 12600 | O3: =Table1[[#This Row],[Gross sales]]*Table1[[#This Row],[Discount_Rate]] -> 630 | P3: =Table1[[#This Row],[Gross sales]]-Table1[[#This Row],[Discount_Amount]] -> 11970 | Q3: =TEXT(Table1[[#This Row],[Date]],"mmmm") -> January | R3: =IF(OR(Table1[[#This Row],[Status]]="Pending",Table1[[#This Row],[Status]]="Refunded"),"Review","OK") -> OK | S3: =IF(Table1[[#This Row],[Net_Sales]]>25000,"Hgh",IF(Table1[[#This Row],[Net_Sales]]>10000,"Medium","Low")) -> Medium | T3: =AND(Table1[[#This Row],[Quantity]]>=5,Table1[[#This Row],[Discount_Rate]]>=10%) -> FALSE | U3: =OR(Table1[[#This Row],[Payment_Method]]="UPI",Table1[[#This Row],[Payment_Method]]="Cash") -> FALSE | V3: =IFERROR(Table1[[#This Row],[Net_Sales]]/Table1[[#This Row],[Quantity]],"ERROR") -> 3990 | W3: =PROPER(TRIM(Table1[[#This Row],[Customer_Name]])) -> Bright Mart | X3: =PROPER(TRIM(Table1[[#This Row],[Region]])) -> South | Y3: =YEAR(Table1[[#This Row],[Date]]) -> 2026 | Z3: =MONTH(Table1[[#This Row],[Date]]) -> 1 | AA3: =MID(Table1[[#This Row],[Transaction_ID]],4,7) -> 1002 | AB3: =_xlfn.CONCAT(Table1[[#This Row],[Region]],"-",Table1[[#This Row],[Category]]) -> South-Home
A4: TXN1003 | B4: 46027 | C4: West | D4: Retail | E4: City Bazaar | F4: Grocery | G4: Rice Bag | H4: 10 | I4: 1250 | J4: 0 | K4: Cash | L4: Completed | M4: EMP02 | N4: =Table1[[#This Row],[Quantity]]*Table1[[#This Row],[Unit_Price_INR]] -> 12500 | O4: =Table1[[#This Row],[Gross sales]]*Table1[[#This Row],[Discount_Rate]] -> 0 | P4: =Table1[[#This Row],[Gross sales]]-Table1[[#This Row],[Discount_Amount]] -> 12500 | Q4: =TEXT(Table1[[#This Row],[Date]],"mmmm") -> January | R4: =IF(OR(Table1[[#This Row],[Status]]="Pending",Table1[[#This Row],[Status]]="Refunded"),"Review","OK") -> OK | S4: =IF(Table1[[#This Row],[Net_Sales]]>25000,"Hgh",IF(Table1[[#This Row],[Net_Sales]]>10000,"Medium","Low")) -> Medium | T4: =AND(Table1[[#This Row],[Quantity]]>=5,Table1[[#This Row],[Discount_Rate]]>=10%) -> FALSE | U4: =OR(Table1[[#This Row],[Payment_Method]]="UPI",Table1[[#This Row],[Payment_Method]]="Cash") -> TRUE | V4: =IFERROR(Table1[[#This Row],[Net_Sales]]/Table1[[#This Row],[Quantity]],"ERROR") -> 1250 | W4: =PROPER(TRIM(Table1[[#This Row],[Customer_Name]])) -> City Bazaar | X4: =PROPER(TRIM(Table1[[#This Row],[Region]])) -> West | Y4: =YEAR(Table1[[#This Row],[Date]]) -> 2026 | Z4: =MONTH(Table1[[#This Row],[Date]]) -> 1 | AA4: =MID(Table1[[#This Row],[Transaction_ID]],4,7) -> 1003 | AB4: =_xlfn.CONCAT(Table1[[#This Row],[Region]],"-",Table1[[#This Row],[Category]]) -> West-Grocery
A5: TXN1004 | B5: 46028 | C5: East | D5: Wholesale | E5: Delta Traders | F5: Office | G5: Printer | H5: 4 | I5: 18500 | J5: 0.1 | K5: Bank Transfer | L5: Completed | M5: EMP04 | N5: =Table1[[#This Row],[Quantity]]*Table1[[#This Row],[Unit_Price_INR]] -> 74000 | O5: =Table1[[#This Row],[Gross sales]]*Table1[[#This Row],[Discount_Rate]] -> 7400 | P5: =Table1[[#This Row],[Gross sales]]-Table1[[#This Row],[Discount_Amount]] -> 66600 | Q5: =TEXT(Table1[[#This Row],[Date]],"mmmm") -> January | R5: =IF(OR(Table1[[#This Row],[Status]]="Pending",Table1[[#This Row],[Status]]="Refunded"),"Review","OK") -> OK | S5: =IF(Table1[[#This Row],[Net_Sales]]>25000,"Hgh",IF(Table1[[#This Row],[Net_Sales]]>10000,"Medium","Low")) -> Hgh | T5: =AND(Table1[[#This Row],[Quantity]]>=5,Table1[[#This Row],[Discount_Rate]]>=10%) -> FALSE | U5: =OR(Table1[[#This Row],[Payment_Method]]="UPI",Table1[[#This Row],[Payment_Method]]="Cash") -> FALSE | V5: =IFERROR(Table1[[#This Row],[Net_Sales]]/Table1[[#This Row],[Quantity]],"ERROR") -> 16650 | W5: =PROPER(TRIM(Table1[[#This Row],[Customer_Name]])) -> Delta Traders | X5: =PROPER(TRIM(Table1[[#This Row],[Region]])) -> East | Y5: =YEAR(Table1[[#This Row],[Date]]) -> 2026 | Z5: =MONTH(Table1[[#This Row],[Date]]) -> 1 | AA5: =MID(Table1[[#This Row],[Transaction_ID]],4,7) -> 1004 | AB5: =_xlfn.CONCAT(Table1[[#This Row],[Region]],"-",Table1[[#This Row],[Category]]) -> East-Office
A6: TXN1005 | B6: 46029 | C6: North | D6: Online | E6: Evergreen Shop | F6: Fashion | G6: Jacket | H6: 5 | I6: 2400 | J6: 0.15 | K6: Card | L6: Completed | M6: EMP01 | N6: =Table1[[#This Row],[Quantity]]*Table1[[#This Row],[Unit_Price_INR]] -> 12000 | O6: =Table1[[#This Row],[Gross sales]]*Table1[[#This Row],[Discount_Rate]] -> 1800 | P6: =Table1[[#This Row],[Gross sales]]-Table1[[#This Row],[Discount_Amount]] -> 10200 | Q6: =TEXT(Table1[[#This Row],[Date]],"mmmm") -> January | R6: =IF(OR(Table1[[#This Row],[Status]]="Pending",Table1[[#This Row],[Status]]="Refunded"),"Review","OK") -> OK | S6: =IF(Table1[[#This Row],[Net_Sales]]>25000,"Hgh",IF(Table1[[#This Row],[Net_Sales]]>10000,"Medium","Low")) -> Medium | T6: =AND(Table1[[#This Row],[Quantity]]>=5,Table1[[#This Row],[Discount_Rate]]>=10%) -> TRUE | U6: =OR(Table1[[#This Row],[Payment_Method]]="UPI",Table1[[#This Row],[Payment_Method]]="Cash") -> FALSE | V6: =IFERROR(Table1[[#This Row],[Net_Sales]]/Table1[[#This Row],[Quantity]],"ERROR") -> 2040 | W6: =PROPER(TRIM(Table1[[#This Row],[Customer_Name]])) -> Evergreen Shop | X6: =PROPER(TRIM(Table1[[#This Row],[Region]])) -> North | Y6: =YEAR(Table1[[#This Row],[Date]]) -> 2026 | Z6: =MONTH(Table1[[#This Row],[Date]]) -> 1 | AA6: =MID(Table1[[#This Row],[Transaction_ID]],4,7) -> 1005 | AB6: =_xlfn.CONCAT(Table1[[#This Row],[Region]],"-",Table1[[#This Row],[Category]]) -> North-Fashion
A7: TXN1006 | B7: 46031 | C7: South | D7: Retail | E7: Fresh Basket | F7: Grocery | G7: Cooking Oil | H7: 12 | I7: 185 | J7: 0.03 | K7: UPI | L7: Completed | M7: EMP05 | N7: =Table1[[#This Row],[Quantity]]*Table1[[#This Row],[Unit_Price_INR]] -> 2220 | O7: =Table1[[#This Row],[Gross sales]]*Table1[[#This Row],[Discount_Rate]] -> 66.6 | P7: =Table1[[#This Row],[Gross sales]]-Table1[[#This Row],[Discount_Amount]] -> 2153.4 | Q7: =TEXT(Table1[[#This Row],[Date]],"mmmm") -> January | R7: =IF(OR(Table1[[#This Row],[Status]]="Pending",Table1[[#This Row],[Status]]="Refunded"),"Review","OK") -> OK | S7: =IF(Table1[[#This Row],[Net_Sales]]>25000,"Hgh",IF(Table1[[#This Row],[Net_Sales]]>10000,"Medium","Low")) -> Low | T7: =AND(Table1[[#This Row],[Quantity]]>=5,Table1[[#This Row],[Discount_Rate]]>=10%) -> FALSE | U7: =OR(Table1[[#This Row],[Payment_Method]]="UPI",Table1[[#This Row],[Payment_Method]]="Cash") -> TRUE | V7: =IFERROR(Table1[[#This Row],[Net_Sales]]/Table1[[#This Row],[Quantity]],"ERROR") -> 179.45 | W7: =PROPER(TRIM(Table1[[#This Row],[Customer_Name]])) -> Fresh Basket | X7: =PROPER(TRIM(Table1[[#This Row],[Region]])) -> South | Y7: =YEAR(Table1[[#This Row],[Date]]) -> 2026 | Z7: =MONTH(Table1[[#This Row],[Date]]) -> 1 | AA7: =MID(Table1[[#This Row],[Transaction_ID]],4,7) -> 1006 | AB7: =_xlfn.CONCAT(Table1[[#This Row],[Region]],"-",Table1[[#This Row],[Category]]) -> South-Grocery
A8: TXN1007 | B8: 46032 | C8: West | D8: Online | E8: Global Needs | F8: Electronics | G8: Headphones | H8: 8 | I8: 1800 | J8: 0.12 | K8: Card | L8: Pending | M8: EMP02 | N8: =Table1[[#This Row],[Quantity]]*Table1[[#This Row],[Unit_Price_INR]] -> 14400 | O8: =Table1[[#This Row],[Gross sales]]*Table1[[#This Row],[Discount_Rate]] -> 1728 | P8: =Table1[[#This Row],[Gross sales]]-Table1[[#This Row],[Discount_Amount]] -> 12672 | Q8: =TEXT(Table1[[#This Row],[Date]],"mmmm") -> January | R8: =IF(OR(Table1[[#This Row],[Status]]="Pending",Table1[[#This Row],[Status]]="Refunded"),"Review","OK") -> Review | S8: =IF(Table1[[#This Row],[Net_Sales]]>25000,"Hgh",IF(Table1[[#This Row],[Net_Sales]]>10000,"Medium","Low")) -> Medium | T8: =AND(Table1[[#This Row],[Quantity]]>=5,Table1[[#This Row],[Discount_Rate]]>=10%) -> TRUE | U8: =OR(Table1[[#This Row],[Payment_Method]]="UPI",Table1[[#This Row],[Payment_Method]]="Cash") -> FALSE | V8: =IFERROR(Table1[[#This Row],[Net_Sales]]/Table1[[#This Row],[Quantity]],"ERROR") -> 1584 | W8: =PROPER(TRIM(Table1[[#This Row],[Customer_Name]])) -> Global Needs | X8: =PROPER(TRIM(Table1[[#This Row],[Region]])) -> West | Y8: =YEAR(Table1[[#This Row],[Date]]) -> 2026 | Z8: =MONTH(Table1[[#This Row],[Date]]) -> 1 | AA8: =MID(Table1[[#This Row],[Transaction_ID]],4,7) -> 1007 | AB8: =_xlfn.CONCAT(Table1[[#This Row],[Region]],"-",Table1[[#This Row],[Category]]) -> West-Electronics
A9: TXN1008 | B9: 46033 | C9: East | D9: Retail | E9: Harbor Supplies | F9: Office | G9: Office Chair | H9: 3 | I9: 7800 | J9: 0.07 | K9: Bank Transfer | L9: Completed | M9: EMP04 | N9: =Table1[[#This Row],[Quantity]]*Table1[[#This Row],[Unit_Price_INR]] -> 23400 | O9: =Table1[[#This Row],[Gross sales]]*Table1[[#This Row],[Discount_Rate]] -> 1638 | P9: =Table1[[#This Row],[Gross sales]]-Table1[[#This Row],[Discount_Amount]] -> 21762 | Q9: =TEXT(Table1[[#This Row],[Date]],"mmmm") -> January | R9: =IF(OR(Table1[[#This Row],[Status]]="Pending",Table1[[#This Row],[Status]]="Refunded"),"Review","OK") -> OK | S9: =IF(Table1[[#This Row],[Net_Sales]]>25000,"Hgh",IF(Table1[[#This Row],[Net_Sales]]>10000,"Medium","Low")) -> Medium | T9: =AND(Table1[[#This Row],[Quantity]]>=5,Table1[[#This Row],[Discount_Rate]]>=10%) -> FALSE | U9: =OR(Table1[[#This Row],[Payment_Method]]="UPI",Table1[[#This Row],[Payment_Method]]="Cash") -> FALSE | V9: =IFERROR(Table1[[#This Row],[Net_Sales]]/Table1[[#This Row],[Quantity]],"ERROR") -> 7254 | W9: =PROPER(TRIM(Table1[[#This Row],[Customer_Name]])) -> Harbor Supplies | X9: =PROPER(TRIM(Table1[[#This Row],[Region]])) -> East | Y9: =YEAR(Table1[[#This Row],[Date]]) -> 2026 | Z9: =MONTH(Table1[[#This Row],[Date]]) -> 1 | AA9: =MID(Table1[[#This Row],[Transaction_ID]],4,7) -> 1008 | AB9: =_xlfn.CONCAT(Table1[[#This Row],[Region]],"-",Table1[[#This Row],[Category]]) -> East-Office
A10: TXN1009 | B10: 46034 | C10: North | D10: Wholesale | E10: Indigo Retailers | F10: Home | G10: Water Purifier | H10: 2 | I10: 14500 | J10: 0.05 | K10: Bank Transfer | L10: Completed | M10: EMP03 | N10: =Table1[[#This Row],[Quantity]]*Table1[[#This Row],[Unit_Price_INR]] -> 29000 | O10: =Table1[[#This Row],[Gross sales]]*Table1[[#This Row],[Discount_Rate]] -> 1450 | P10: =Table1[[#This Row],[Gross sales]]-Table1[[#This Row],[Discount_Amount]] -> 27550 | Q10: =TEXT(Table1[[#This Row],[Date]],"mmmm") -> January | R10: =IF(OR(Table1[[#This Row],[Status]]="Pending",Table1[[#This Row],[Status]]="Refunded"),"Review","OK") -> OK | S10: =IF(Table1[[#This Row],[Net_Sales]]>25000,"Hgh",IF(Table1[[#This Row],[Net_Sales]]>10000,"Medium","Low")) -> Hgh | T10: =AND(Table1[[#This Row],[Quantity]]>=5,Table1[[#This Row],[Discount_Rate]]>=10%) -> FALSE | U10: =OR(Table1[[#This Row],[Payment_Method]]="UPI",Table1[[#This Row],[Payment_Method]]="Cash") -> FALSE | V10: =IFERROR(Table1[[#This Row],[Net_Sales]]/Table1[[#This Row],[Quantity]],"ERROR") -> 13775 | W10: =PROPER(TRIM(Table1[[#This Row],[Customer_Name]])) -> Indigo Retailers | X10: =PROPER(TRIM(Table1[[#This Row],[Region]])) -> North | Y10: =YEAR(Table1[[#This Row],[Date]]) -> 2026 | Z10: =MONTH(Table1[[#This Row],[Date]]) -> 1 | AA10: =MID(Table1[[#This Row],[Transaction_ID]],4,7) -> 1009 | AB10: =_xlfn.CONCAT(Table1[[#This Row],[Region]],"-",Table1[[#This Row],[Category]]) -> North-Home
A11: TXN1010 | B11: 46036 | C11: South | D11: Online | E11: Jasmine Market | F11: Fashion | G11: Shoes | H11: 6 | I11: 3200 | J11: 0.2 | K11: UPI | L11: Refunded | M11: EMP05 | N11: =Table1[[#This Row],[Quantity]]*Table1[[#This Row],[Unit_Price_INR]] -> 19200 | O11: =Table1[[#This Row],[Gross sales]]*Table1[[#This Row],[Discount_Rate]] -> 3840 | P11: =Table1[[#This Row],[Gross sales]]-Table1[[#This Row],[Discount_Amount]] -> 15360 | Q11: =TEXT(Table1[[#This Row],[Date]],"mmmm") -> January | R11: =IF(OR(Table1[[#This Row],[Status]]="Pending",Table1[[#This Row],[Status]]="Refunded"),"Review","OK") -> Review | S11: =IF(Table1[[#This Row],[Net_Sales]]>25000,"Hgh",IF(Table1[[#This Row],[Net_Sales]]>10000,"Medium","Low")) -> Medium | T11: =AND(Table1[[#This Row],[Quantity]]>=5,Table1[[#This Row],[Discount_Rate]]>=10%) -> TRUE | U11: =OR(Table1[[#This Row],[Payment_Method]]="UPI",Table1[[#This Row],[Payment_Method]]="Cash") -> TRUE | V11: =IFERROR(Table1[[#This Row],[Net_Sales]]/Table1[[#This Row],[Quantity]],"ERROR") -> 2560 | W11: =PROPER(TRIM(Table1[[#This Row],[Customer_Name]])) -> Jasmine Market | X11: =PROPER(TRIM(Table1[[#This Row],[Region]])) -> South | Y11: =YEAR(Table1[[#This Row],[Date]]) -> 2026 | Z11: =MONTH(Table1[[#This Row],[Date]]) -> 1 | AA11: =MID(Table1[[#This Row],[Transaction_ID]],4,7) -> 1010 | AB11: =_xlfn.CONCAT(Table1[[#This Row],[Region]],"-",Table1[[#This Row],[Category]]) -> South-Fashion
A12: TXN1011 | B12: 46037 | C12: West | D12: Retail | E12: Kingfisher Store | F12: Electronics | G12: Monitor | H12: 4 | I12: 11200 | J12: 0.08 | K12: Card | L12: Completed | M12: EMP02 | N12: =Table1[[#This Row],[Quantity]]*Table1[[#This Row],[Unit_Price_INR]] -> 44800 | O12: =Table1[[#This Row],[Gross sales]]*Table1[[#This Row],[Discount_Rate]] -> 3584 | P12: =Table1[[#This Row],[Gross sales]]-Table1[[#This Row],[Discount_Amount]] -> 41216 | Q12: =TEXT(Table1[[#This Row],[Date]],"mmmm") -> January | R12: =IF(OR(Table1[[#This Row],[Status]]="Pending",Table1[[#This Row],[Status]]="Refunded"),"Review","OK") -> OK | S12: =IF(Table1[[#This Row],[Net_Sales]]>25000,"Hgh",IF(Table1[[#This Row],[Net_Sales]]>10000,"Medium","Low")) -> Hgh | T12: =AND(Table1[[#This Row],[Quantity]]>=5,Table1[[#This Row],[Discount_Rate]]>=10%) -> FALSE | U12: =OR(Table1[[#This Row],[Payment_Method]]="UPI",Table1[[#This Row],[Payment_Method]]="Cash") -> FALSE | V12: =IFERROR(Table1[[#This Row],[Net_Sales]]/Table1[[#This Row],[Quantity]],"ERROR") -> 10304 | W12: =PROPER(TRIM(Table1[[#This Row],[Customer_Name]])) -> Kingfisher Store | X12: =PROPER(TRIM(Table1[[#This Row],[Region]])) -> West | Y12: =YEAR(Table1[[#This Row],[Date]]) -> 2026 | Z12: =MONTH(Table1[[#This Row],[Date]]) -> 1 | AA12: =MID(Table1[[#This Row],[Transaction_ID]],4,7) -> 1011 | AB12: =_xlfn.CONCAT(Table1[[#This Row],[Region]],"-",Table1[[#This Row],[Category]]) -> West-Electronics
A13: TXN1012 | B13: 46039 | C13: East | D13: Wholesale | E13: Lotus Distributors | F13: Grocery | G13: Wheat Flour | H13: 20 | I13: 650 | J13: 0.02 | K13: Bank Transfer | L13: Completed | M13: EMP04 | N13: =Table1[[#This Row],[Quantity]]*Table1[[#This Row],[Unit_Price_INR]] -> 13000 | O13: =Table1[[#This Row],[Gross sales]]*Table1[[#This Row],[Discount_Rate]] -> 260 | P13: =Table1[[#This Row],[Gross sales]]-Table1[[#This Row],[Discount_Amount]] -> 12740 | Q13: =TEXT(Table1[[#This Row],[Date]],"mmmm") -> January | R13: =IF(OR(Table1[[#This Row],[Status]]="Pending",Table1[[#This Row],[Status]]="Refunded"),"Review","OK") -> OK | S13: =IF(Table1[[#This Row],[Net_Sales]]>25000,"Hgh",IF(Table1[[#This Row],[Net_Sales]]>10000,"Medium","Low")) -> Medium | T13: =AND(Table1[[#This Row],[Quantity]]>=5,Table1[[#This Row],[Discount_Rate]]>=10%) -> FALSE | U13: =OR(Table1[[#This Row],[Payment_Method]]="UPI",Table1[[#This Row],[Payment_Method]]="Cash") -> FALSE | V13: =IFERROR(Table1[[#This Row],[Net_Sales]]/Table1[[#This Row],[Quantity]],"ERROR") -> 637 | W13: =PROPER(TRIM(Table1[[#This Row],[Customer_Name]])) -> Lotus Distributors | X13: =PROPER(TRIM(Table1[[#This Row],[Region]])) -> East | Y13: =YEAR(Table1[[#This Row],[Date]]) -> 2026 | Z13: =MONTH(Table1[[#This Row],[Date]]) -> 1 | AA13: =MID(Table1[[#This Row],[Transaction_ID]],4,7) -> 1012 | AB13: =_xlfn.CONCAT(Table1[[#This Row],[Region]],"-",Table1[[#This Row],[Category]]) -> East-Grocery
... A77: TXN1077 | B77: 46172 | C77: East | D77: Wholesale | E77: Xylem Traders | F77: Home | G77: Storage Rack | H77: 2 | I77: 4800 | J77: 0.06 | K77: Bank Transfer | L77: Completed | M77: EMP04 | N77: =Table1[[#This Row],[Quantity]]*Table1[[#This Row],[Unit_Price_INR]] -> 9600 | O77: =Table1[[#This Row],[Gross sales]]*Table1[[#This Row],[Discount_Rate]] -> 576 | P77: =Table1[[#This Row],[Gross sales]]-Table1[[#This Row],[Discount_Amount]] -> 9024 | Q77: =TEXT(Table1[[#This Row],[Date]],"mmmm") -> May | R77: =IF(OR(Table1[[#This Row],[Status]]="Pending",Table1[[#This Row],[Status]]="Refunded"),"Review","OK") -> OK | S77: =IF(Table1[[#This Row],[Net_Sales]]>25000,"Hgh",IF(Table1[[#This Row],[Net_Sales]]>10000,"Medium","Low")) -> Low | T77: =AND(Table1[[#This Row],[Quantity]]>=5,Table1[[#This Row],[Discount_Rate]]>=10%) -> FALSE | U77: =OR(Table1[[#This Row],[Payment_Method]]="UPI",Table1[[#This Row],[Payment_Method]]="Cash") -> FALSE | V77: =IFERROR(Table1[[#This Row],[Net_Sales]]/Table1[[#This Row],[Quantity]],"ERROR") -> 4512 | W77: =PROPER(TRIM(Table1[[#This Row],[Customer_Name]])) -> Xylem Traders | X77: =PROPER(TRIM(Table1[[#This Row],[Region]])) -> East | Y77: =YEAR(Table1[[#This Row],[Date]]) -> 2026 | Z77: =MONTH(Table1[[#This Row],[Date]]) -> 5 | AA77: =MID(Table1[[#This Row],[Transaction_ID]],4,7) -> 1077 | AB77: =_xlfn.CONCAT(Table1[[#This Row],[Region]],"-",Table1[[#This Row],[Category]]) -> East-Home
H79: =SUM(Table1[Quantity]) -> 592 | P79: =SUM(Table1[Net_Sales]) -> 1594263.8

Sheet filter
A1: Transaction_ID | B1: Date | C1: Region | D1: Sales_Channel | E1: Customer_Name | F1: Category | G1: Product | H1: Quantity | I1: Unit_Price_INR | J1: Discount_Rate | K1: Payment_Method | L1: Status | M1: Sales_Rep_ID | N1: Gross sales | O1: Discount_Amount | P1: Net_Sales | Q1: Transaction_month | R1: Transaction_Flag | S1: classification_netsales | T1: AND | U1: OR | V1: iferror | W1: T21 | X1: T22 | Y1: Year | Z1: Month | AA1: id | AB1: Region_category
A2: TXN1001 | B2: 46025 | C2: North | D2: Retail | E2: Asha Stores | F2: Electronics | G2: Laptop | H2: 2 | I2: 52000 | J2: 0.08 | K2: UPI | L2: Completed | M2: EMP01 | N2: =Table16[[#This Row],[Quantity]]*Table16[[#This Row],[Unit_Price_INR]] -> 104000 | O2: =Table16[[#This Row],[Gross sales]]*Table16[[#This Row],[Discount_Rate]] -> 8320 | P2: =Table16[[#This Row],[Gross sales]]-Table16[[#This Row],[Discount_Amount]] -> 95680 | Q2: =TEXT(Table16[[#This Row],[Date]],"mmmm") -> January | R2: =IF(OR(Table16[[#This Row],[Status]]="Pending",Table16[[#This Row],[Status]]="Refunded"),"Review","OK") -> OK | S2: =IF(Table16[[#This Row],[Net_Sales]]>25000,"Hgh",IF(Table16[[#This Row],[Net_Sales]]>10000,"Medium","Low")) -> Hgh | T2: =AND(Table16[[#This Row],[Quantity]]>=5,Table16[[#This Row],[Discount_Rate]]>=10%) -> FALSE | U2: =OR(Table16[[#This Row],[Payment_Method]]="UPI",Table16[[#This Row],[Payment_Method]]="Cash") -> TRUE | V2: =IFERROR(Table16[[#This Row],[Net_Sales]]/Table16[[#This Row],[Quantity]],"ERROR") -> 47840 | W2: =PROPER(TRIM(Table16[[#This Row],[Customer_Name]])) -> Asha Stores | X2: =PROPER(TRIM(Table16[[#This Row],[Region]])) -> North | Y2: =YEAR(Table16[[#This Row],[Date]]) -> 2026 | Z2: =MONTH(Table16[[#This Row],[Date]]) -> 1 | AA2: =MID(Table16[[#This Row],[Transaction_ID]],4,7) -> 1001 | AB2: =_xlfn.CONCAT(Table16[[#This Row],[Region]],"-",Table16[[#This Row],[Category]]) -> North-Electronics
A3: TXN1002 | B3: 46026 | C3: South | D3: Online | E3: Bright Mart | F3: Home | G3: Mixer Grinder | H3: 3 | I3: 4200 | J3: 0.05 | K3: Card | L3: Completed | M3: EMP03 | N3: =Table16[[#This Row],[Quantity]]*Table16[[#This Row],[Unit_Price_INR]] -> 12600 | O3: =Table16[[#This Row],[Gross sales]]*Table16[[#This Row],[Discount_Rate]] -> 630 | P3: =Table16[[#This Row],[Gross sales]]-Table16[[#This Row],[Discount_Amount]] -> 11970 | Q3: =TEXT(Table16[[#This Row],[Date]],"mmmm") -> January | R3: =IF(OR(Table16[[#This Row],[Status]]="Pending",Table16[[#This Row],[Status]]="Refunded"),"Review","OK") -> OK | S3: =IF(Table16[[#This Row],[Net_Sales]]>25000,"Hgh",IF(Table16[[#This Row],[Net_Sales]]>10000,"Medium","Low")) -> Medium | T3: =AND(Table16[[#This Row],[Quantity]]>=5,Table16[[#This Row],[Discount_Rate]]>=10%) -> FALSE | U3: =OR(Table16[[#This Row],[Payment_Method]]="UPI",Table16[[#This Row],[Payment_Method]]="Cash") -> FALSE | V3: =IFERROR(Table16[[#This Row],[Net_Sales]]/Table16[[#This Row],[Quantity]],"ERROR") -> 3990 | W3: =PROPER(TRIM(Table16[[#This Row],[Customer_Name]])) -> Bright Mart | X3: =PROPER(TRIM(Table16[[#This Row],[Region]])) -> South | Y3: =YEAR(Table16[[#This Row],[Date]]) -> 2026 | Z3: =MONTH(Table16[[#This Row],[Date]]) -> 1 | AA3: =MID(Table16[[#This Row],[Transaction_ID]],4,7) -> 1002 | AB3: =_xlfn.CONCAT(Table16[[#This Row],[Region]],"-",Table16[[#This Row],[Category]]) -> South-Home
A4: TXN1003 | B4: 46027 | C4: West | D4: Retail | E4: City Bazaar | F4: Grocery | G4: Rice Bag | H4: 10 | I4: 1250 | J4: 0 | K4: Cash | L4: Completed | M4: EMP02 | N4: =Table16[[#This Row],[Quantity]]*Table16[[#This Row],[Unit_Price_INR]] -> 12500 | O4: =Table16[[#This Row],[Gross sales]]*Table16[[#This Row],[Discount_Rate]] -> 0 | P4: =Table16[[#This Row],[Gross sales]]-Table16[[#This Row],[Discount_Amount]] -> 12500 | Q4: =TEXT(Table16[[#This Row],[Date]],"mmmm") -> January | R4: =IF(OR(Table16[[#This Row],[Status]]="Pending",Table16[[#This Row],[Status]]="Refunded"),"Review","OK") -> OK | S4: =IF(Table16[[#This Row],[Net_Sales]]>25000,"Hgh",IF(Table16[[#This Row],[Net_Sales]]>10000,"Medium","Low")) -> Medium | T4: =AND(Table16[[#This Row],[Quantity]]>=5,Table16[[#This Row],[Discount_Rate]]>=10%) -> FALSE | U4: =OR(Table16[[#This Row],[Payment_Method]]="UPI",Table16[[#This Row],[Payment_Method]]="Cash") -> TRUE | V4: =IFERROR(Table16[[#This Row],[Net_Sales]]/Table16[[#This Row],[Quantity]],"ERROR") -> 1250 | W4: =PROPER(TRIM(Table16[[#This Row],[Customer_Name]])) -> City Bazaar | X4: =PROPER(TRIM(Table16[[#This Row],[Region]])) -> West | Y4: =YEAR(Table16[[#This Row],[Date]]) -> 2026 | Z4: =MONTH(Table16[[#This Row],[Date]]) -> 1 | AA4: =MID(Table16[[#This Row],[Transaction_ID]],4,7) -> 1003 | AB4: =_xlfn.CONCAT(Table16[[#This Row],[Region]],"-",Table16[[#This Row],[Category]]) -> West-Grocery
A5: TXN1004 | B5: 46028 | C5: East | D5: Wholesale | E5: Delta Traders | F5: Office | G5: Printer | H5: 4 | I5: 18500 | J5: 0.1 | K5: Bank Transfer | L5: Completed | M5: EMP04 | N5: =Table16[[#This Row],[Quantity]]*Table16[[#This Row],[Unit_Price_INR]] -> 74000 | O5: =Table16[[#This Row],[Gross sales]]*Table16[[#This Row],[Discount_Rate]] -> 7400 | P5: =Table16[[#This Row],[Gross sales]]-Table16[[#This Row],[Discount_Amount]] -> 66600 | Q5: =TEXT(Table16[[#This Row],[Date]],"mmmm") -> January | R5: =IF(OR(Table16[[#This Row],[Status]]="Pending",Table16[[#This Row],[Status]]="Refunded"),"Review","OK") -> OK | S5: =IF(Table16[[#This Row],[Net_Sales]]>25000,"Hgh",IF(Table16[[#This Row],[Net_Sales]]>10000,"Medium","Low")) -> Hgh | T5: =AND(Table16[[#This Row],[Quantity]]>=5,Table16[[#This Row],[Discount_Rate]]>=10%) -> FALSE | U5: =OR(Table16[[#This Row],[Payment_Method]]="UPI",Table16[[#This Row],[Payment_Method]]="Cash") -> FALSE | V5: =IFERROR(Table16[[#This Row],[Net_Sales]]/Table16[[#This Row],[Quantity]],"ERROR") -> 16650 | W5: =PROPER(TRIM(Table16[[#This Row],[Customer_Name]])) -> Delta Traders | X5: =PROPER(TRIM(Table16[[#This Row],[Region]])) -> East | Y5: =YEAR(Table16[[#This Row],[Date]]) -> 2026 | Z5: =MONTH(Table16[[#This Row],[Date]]) -> 1 | AA5: =MID(Table16[[#This Row],[Transaction_ID]],4,7) -> 1004 | AB5: =_xlfn.CONCAT(Table16[[#This Row],[Region]],"-",Table16[[#This Row],[Category]]) -> East-Office
A6: TXN1005 | B6: 46029 | C6: North | D6: Online | E6: Evergreen Shop | F6: Fashion | G6: Jacket | H6: 5 | I6: 2400 | J6: 0.15 | K6: Card | L6: Completed | M6: EMP01 | N6: =Table16[[#This Row],[Quantity]]*Table16[[#This Row],[Unit_Price_INR]] -> 12000 | O6: =Table16[[#This Row],[Gross sales]]*Table16[[#This Row],[Discount_Rate]] -> 1800 | P6: =Table16[[#This Row],[Gross sales]]-Table16[[#This Row],[Discount_Amount]] -> 10200 | Q6: =TEXT(Table16[[#This Row],[Date]],"mmmm") -> January | R6: =IF(OR(Table16[[#This Row],[Status]]="Pending",Table16[[#This Row],[Status]]="Refunded"),"Review","OK") -> OK | S6: =IF(Table16[[#This Row],[Net_Sales]]>25000,"Hgh",IF(Table16[[#This Row],[Net_Sales]]>10000,"Medium","Low")) -> Medium | T6: =AND(Table16[[#This Row],[Quantity]]>=5,Table16[[#This Row],[Discount_Rate]]>=10%) -> TRUE | U6: =OR(Table16[[#This Row],[Payment_Method]]="UPI",Table16[[#This Row],[Payment_Method]]="Cash") -> FALSE | V6: =IFERROR(Table16[[#This Row],[Net_Sales]]/Table16[[#This Row],[Quantity]],"ERROR") -> 2040 | W6: =PROPER(TRIM(Table16[[#This Row],[Customer_Name]])) -> Evergreen Shop | X6: =PROPER(TRIM(Table16[[#This Row],[Region]])) -> North | Y6: =YEAR(Table16[[#This Row],[Date]]) -> 2026 | Z6: =MONTH(Table16[[#This Row],[Date]]) -> 1 | AA6: =MID(Table16[[#This Row],[Transaction_ID]],4,7) -> 1005 | AB6: =_xlfn.CONCAT(Table16[[#This Row],[Region]],"-",Table16[[#This Row],[Category]]) -> North-Fashion
A7: TXN1006 | B7: 46031 | C7: South | D7: Retail | E7: Fresh Basket | F7: Grocery | G7: Cooking Oil | H7: 12 | I7: 185 | J7: 0.03 | K7: UPI | L7: Completed | M7: EMP05 | N7: =Table16[[#This Row],[Quantity]]*Table16[[#This Row],[Unit_Price_INR]] -> 2220 | O7: =Table16[[#This Row],[Gross sales]]*Table16[[#This Row],[Discount_Rate]] -> 66.6 | P7: =Table16[[#This Row],[Gross sales]]-Table16[[#This Row],[Discount_Amount]] -> 2153.4 | Q7: =TEXT(Table16[[#This Row],[Date]],"mmmm") -> January | R7: =IF(OR(Table16[[#This Row],[Status]]="Pending",Table16[[#This Row],[Status]]="Refunded"),"Review","OK") -> OK | S7: =IF(Table16[[#This Row],[Net_Sales]]>25000,"Hgh",IF(Table16[[#This Row],[Net_Sales]]>10000,"Medium","Low")) -> Low | T7: =AND(Table16[[#This Row],[Quantity]]>=5,Table16[[#This Row],[Discount_Rate]]>=10%) -> FALSE | U7: =OR(Table16[[#This Row],[Payment_Method]]="UPI",Table16[[#This Row],[Payment_Method]]="Cash") -> TRUE | V7: =IFERROR(Table16[[#This Row],[Net_Sales]]/Table16[[#This Row],[Quantity]],"ERROR") -> 179.45 | W7: =PROPER(TRIM(Table16[[#This Row],[Customer_Name]])) -> Fresh Basket | X7: =PROPER(TRIM(Table16[[#This Row],[Region]])) -> South | Y7: =YEAR(Table16[[#This Row],[Date]]) -> 2026 | Z7: =MONTH(Table16[[#This Row],[Date]]) -> 1 | AA7: =MID(Table16[[#This Row],[Transaction_ID]],4,7) -> 1006 | AB7: =_xlfn.CONCAT(Table16[[#This Row],[Region]],"-",Table16[[#This Row],[Category]]) -> South-Grocery
A8: TXN1007 | B8: 46032 | C8: West | D8: Online | E8: Global Needs | F8: Electronics | G8: Headphones | H8: 8 | I8: 1800 | J8: 0.12 | K8: Card | L8: Pending | M8: EMP02 | N8: =Table16[[#This Row],[Quantity]]*Table16[[#This Row],[Unit_Price_INR]] -> 14400 | O8: =Table16[[#This Row],[Gross sales]]*Table16[[#This Row],[Discount_Rate]] -> 1728 | P8: =Table16[[#This Row],[Gross sales]]-Table16[[#This Row],[Discount_Amount]] -> 12672 | Q8: =TEXT(Table16[[#This Row],[Date]],"mmmm") -> January | R8: =IF(OR(Table16[[#This Row],[Status]]="Pending",Table16[[#This Row],[Status]]="Refunded"),"Review","OK") -> Review | S8: =IF(Table16[[#This Row],[Net_Sales]]>25000,"Hgh",IF(Table16[[#This Row],[Net_Sales]]>10000,"Medium","Low")) -> Medium | T8: =AND(Table16[[#This Row],[Quantity]]>=5,Table16[[#This Row],[Discount_Rate]]>=10%) -> TRUE | U8: =OR(Table16[[#This Row],[Payment_Method]]="UPI",Table16[[#This Row],[Payment_Method]]="Cash") -> FALSE | V8: =IFERROR(Table16[[#This Row],[Net_Sales]]/Table16[[#This Row],[Quantity]],"ERROR") -> 1584 | W8: =PROPER(TRIM(Table16[[#This Row],[Customer_Name]])) -> Global Needs | X8: =PROPER(TRIM(Table16[[#This Row],[Region]])) -> West | Y8: =YEAR(Table16[[#This Row],[Date]]) -> 2026 | Z8: =MONTH(Table16[[#This Row],[Date]]) -> 1 | AA8: =MID(Table16[[#This Row],[Transaction_ID]],4,7) -> 1007 | AB8: =_xlfn.CONCAT(Table16[[#This Row],[Region]],"-",Table16[[#This Row],[Category]]) -> West-Electronics
A9: TXN1008 | B9: 46033 | C9: East | D9: Retail | E9: Harbor Supplies | F9: Office | G9: Office Chair | H9: 3 | I9: 7800 | J9: 0.07 | K9: Bank Transfer | L9: Completed | M9: EMP04 | N9: =Table16[[#This Row],[Quantity]]*Table16[[#This Row],[Unit_Price_INR]] -> 23400 | O9: =Table16[[#This Row],[Gross sales]]*Table16[[#This Row],[Discount_Rate]] -> 1638 | P9: =Table16[[#This Row],[Gross sales]]-Table16[[#This Row],[Discount_Amount]] -> 21762 | Q9: =TEXT(Table16[[#This Row],[Date]],"mmmm") -> January | R9: =IF(OR(Table16[[#This Row],[Status]]="Pending",Table16[[#This Row],[Status]]="Refunded"),"Review","OK") -> OK | S9: =IF(Table16[[#This Row],[Net_Sales]]>25000,"Hgh",IF(Table16[[#This Row],[Net_Sales]]>10000,"Medium","Low")) -> Medium | T9: =AND(Table16[[#This Row],[Quantity]]>=5,Table16[[#This Row],[Discount_Rate]]>=10%) -> FALSE | U9: =OR(Table16[[#This Row],[Payment_Method]]="UPI",Table16[[#This Row],[Payment_Method]]="Cash") -> FALSE | V9: =IFERROR(Table16[[#This Row],[Net_Sales]]/Table16[[#This Row],[Quantity]],"ERROR") -> 7254 | W9: =PROPER(TRIM(Table16[[#This Row],[Customer_Name]])) -> Harbor Supplies | X9: =PROPER(TRIM(Table16[[#This Row],[Region]])) -> East | Y9: =YEAR(Table16[[#This Row],[Date]]) -> 2026 | Z9: =MONTH(Table16[[#This Row],[Date]]) -> 1 | AA9: =MID(Table16[[#This Row],[Transaction_ID]],4,7) -> 1008 | AB9: =_xlfn.CONCAT(Table16[[#This Row],[Region]],"-",Table16[[#This Row],[Category]]) -> East-Office
A10: TXN1009 | B10: 46034 | C10: North | D10: Wholesale | E10: Indigo Retailers | F10: Home | G10: Water Purifier | H10: 2 | I10: 14500 | J10: 0.05 | K10: Bank Transfer | L10: Completed | M10: EMP03 | N10: =Table16[[#This Row],[Quantity]]*Table16[[#This Row],[Unit_Price_INR]] -> 29000 | O10: =Table16[[#This Row],[Gross sales]]*Table16[[#This Row],[Discount_Rate]] -> 1450 | P10: =Table16[[#This Row],[Gross sales]]-Table16[[#This Row],[Discount_Amount]] -> 27550 | Q10: =TEXT(Table16[[#This Row],[Date]],"mmmm") -> January | R10: =IF(OR(Table16[[#This Row],[Status]]="Pending",Table16[[#This Row],[Status]]="Refunded"),"Review","OK") -> OK | S10: =IF(Table16[[#This Row],[Net_Sales]]>25000,"Hgh",IF(Table16[[#This Row],[Net_Sales]]>10000,"Medium","Low")) -> Hgh | T10: =AND(Table16[[#This Row],[Quantity]]>=5,Table16[[#This Row],[Discount_Rate]]>=10%) -> FALSE | U10: =OR(Table16[[#This Row],[Payment_Method]]="UPI",Table16[[#This Row],[Payment_Method]]="Cash") -> FALSE | V10: =IFERROR(Table16[[#This Row],[Net_Sales]]/Table16[[#This Row],[Quantity]],"ERROR") -> 13775 | W10: =PROPER(TRIM(Table16[[#This Row],[Customer_Name]])) -> Indigo Retailers | X10: =PROPER(TRIM(Table16[[#This Row],[Region]])) -> North | Y10: =YEAR(Table16[[#This Row],[Date]]) -> 2026 | Z10: =MONTH(Table16[[#This Row],[Date]]) -> 1 | AA10: =MID(Table16[[#This Row],[Transaction_ID]],4,7) -> 1009 | AB10: =_xlfn.CONCAT(Table16[[#This Row],[Region]],"-",Table16[[#This Row],[Category]]) -> North-Home
A11: TXN1010 | B11: 46036 | C11: South | D11: Online | E11: Jasmine Market | F11: Fashion | G11: Shoes | H11: 6 | I11: 3200 | J11: 0.2 | K11: UPI | L11: Refunded | M11: EMP05 | N11: =Table16[[#This Row],[Quantity]]*Table16[[#This Row],[Unit_Price_INR]] -> 19200 | O11: =Table16[[#This Row],[Gross sales]]*Table16[[#This Row],[Discount_Rate]] -> 3840 | P11: =Table16[[#This Row],[Gross sales]]-Table16[[#This Row],[Discount_Amount]] -> 15360 | Q11: =TEXT(Table16[[#This Row],[Date]],"mmmm") -> January | R11: =IF(OR(Table16[[#This Row],[Status]]="Pending",Table16[[#This Row],[Status]]="Refunded"),"Review","OK") -> Review | S11: =IF(Table16[[#This Row],[Net_Sales]]>25000,"Hgh",IF(Table16[[#This Row],[Net_Sales]]>10000,"Medium","Low")) -> Medium | T11: =AND(Table16[[#This Row],[Quantity]]>=5,Table16[[#This Row],[Discount_Rate]]>=10%) -> TRUE | U11: =OR(Table16[[#This Row],[Payment_Method]]="UPI",Table16[[#This Row],[Payment_Method]]="Cash") -> TRUE | V11: =IFERROR(Table16[[#This Row],[Net_Sales]]/Table16[[#This Row],[Quantity]],"ERROR") -> 2560 | W11: =PROPER(TRIM(Table16[[#This Row],[Customer_Name]])) -> Jasmine Market | X11: =PROPER(TRIM(Table16[[#This Row],[Region]])) -> South | Y11: =YEAR(Table16[[#This Row],[Date]]) -> 2026 | Z11: =MONTH(Table16[[#This Row],[Date]]) -> 1 | AA11: =MID(Table16[[#This Row],[Transaction_ID]],4,7) -> 1010 | AB11: =_xlfn.CONCAT(Table16[[#This Row],[Region]],"-",Table16[[#This Row],[Category]]) -> South-Fashion
A12: TXN1011 | B12: 46037 | C12: West | D12: Retail | E12: Kingfisher Store | F12: Electronics | G12: Monitor | H12: 4 | I12: 11200 | J12: 0.08 | K12: Card | L12: Completed | M12: EMP02 | N12: =Table16[[#This Row],[Quantity]]*Table16[[#This Row],[Unit_Price_INR]] -> 44800 | O12: =Table16[[#This Row],[Gross sales]]*Table16[[#This Row],[Discount_Rate]] -> 3584 | P12: =Table16[[#This Row],[Gross sales]]-Table16[[#This Row],[Discount_Amount]] -> 41216 | Q12: =TEXT(Table16[[#This Row],[Date]],"mmmm") -> January | R12: =IF(OR(Table16[[#This Row],[Status]]="Pending",Table16[[#This Row],[Status]]="Refunded"),"Review","OK") -> OK | S12: =IF(Table16[[#This Row],[Net_Sales]]>25000,"Hgh",IF(Table16[[#This Row],[Net_Sales]]>10000,"Medium","Low")) -> Hgh | T12: =AND(Table16[[#This Row],[Quantity]]>=5,Table16[[#This Row],[Discount_Rate]]>=10%) -> FALSE | U12: =OR(Table16[[#This Row],[Payment_Method]]="UPI",Table16[[#This Row],[Payment_Method]]="Cash") -> FALSE | V12: =IFERROR(Table16[[#This Row],[Net_Sales]]/Table16[[#This Row],[Quantity]],"ERROR") -> 10304 | W12: =PROPER(TRIM(Table16[[#This Row],[Customer_Name]])) -> Kingfisher Store | X12: =PROPER(TRIM(Table16[[#This Row],[Region]])) -> West | Y12: =YEAR(Table16[[#This Row],[Date]]) -> 2026 | Z12: =MONTH(Table16[[#This Row],[Date]]) -> 1 | AA12: =MID(Table16[[#This Row],[Transaction_ID]],4,7) -> 1011 | AB12: =_xlfn.CONCAT(Table16[[#This Row],[Region]],"-",Table16[[#This Row],[Category]]) -> West-Electronics
A13: TXN1012 | B13: 46039 | C13: East | D13: Wholesale | E13: Lotus Distributors | F13: Grocery | G13: Wheat Flour | H13: 20 | I13: 650 | J13: 0.02 | K13: Bank Transfer | L13: Completed | M13: EMP04 | N13: =Table16[[#This Row],[Quantity]]*Table16[[#This Row],[Unit_Price_INR]] -> 13000 | O13: =Table16[[#This Row],[Gross sales]]*Table16[[#This Row],[Discount_Rate]] -> 260 | P13: =Table16[[#This Row],[Gross sales]]-Table16[[#This Row],[Discount_Amount]] -> 12740 | Q13: =TEXT(Table16[[#This Row],[Date]],"mmmm") -> January | R13: =IF(OR(Table16[[#This Row],[Status]]="Pending",Table16[[#This Row],[Status]]="Refunded"),"Review","OK") -> OK | S13: =IF(Table16[[#This Row],[Net_Sales]]>25000,"Hgh",IF(Table16[[#This Row],[Net_Sales]]>10000,"Medium","Low")) -> Medium | T13: =AND(Table16[[#This Row],[Quantity]]>=5,Table16[[#This Row],[Discount_Rate]]>=10%) -> FALSE | U13: =OR(Table16[[#This Row],[Payment_Method]]="UPI",Table16[[#This Row],[Payment_Method]]="Cash") -> FALSE | V13: =IFERROR(Table16[[#This Row],[Net_Sales]]/Table16[[#This Row],[Quantity]],"ERROR") -> 637 | W13: =PROPER(TRIM(Table16[[#This Row],[Customer_Name]])) -> Lotus Distributors | X13: =PROPER(TRIM(Table16[[#This Row],[Region]])) -> East | Y13: =YEAR(Table16[[#This Row],[Date]]) -> 2026 | Z13: =MONTH(Table16[[#This Row],[Date]]) -> 1 | AA13: =MID(Table16[[#This Row],[Transaction_ID]],4,7) -> 1012 | AB13: =_xlfn.CONCAT(Table16[[#This Row],[Region]],"-",Table16[[#This Row],[Category]]) -> East-Grocery
... A77: TXN1077 | B77: 46172 | C77: East | D77: Wholesale | E77: Xylem Traders | F77: Home | G77: Storage Rack | H77: 2 | I77: 4800 | J77: 0.06 | K77: Bank Transfer | L77: Completed | M77: EMP04 | N77: =Table16[[#This Row],[Quantity]]*Table16[[#This Row],[Unit_Price_INR]] -> 9600 | O77: =Table16[[#This Row],[Gross sales]]*Table16[[#This Row],[Discount_Rate]] -> 576 | P77: =Table16[[#This Row],[Gross sales]]-Table16[[#This Row],[Discount_Amount]] -> 9024 | Q77: =TEXT(Table16[[#This Row],[Date]],"mmmm") -> May | R77: =IF(OR(Table16[[#This Row],[Status]]="Pending",Table16[[#This Row],[Status]]="Refunded"),"Review","OK") -> OK | S77: =IF(Table16[[#This Row],[Net_Sales]]>25000,"Hgh",IF(Table16[[#This Row],[Net_Sales]]>10000,"Medium","Low")) -> Low | T77: =AND(Table16[[#This Row],[Quantity]]>=5,Table16[[#This Row],[Discount_Rate]]>=10%) -> FALSE | U77: =OR(Table16[[#This Row],[Payment_Method]]="UPI",Table16[[#This Row],[Payment_Method]]="Cash") -> FALSE | V77: =IFERROR(Table16[[#This Row],[Net_Sales]]/Table16[[#This Row],[Quantity]],"ERROR") -> 4512 | W77: =PROPER(TRIM(Table16[[#This Row],[Customer_Name]])) -> Xylem Traders | X77: =PROPER(TRIM(Table16[[#This Row],[Region]])) -> East | Y77: =YEAR(Table16[[#This Row],[Date]]) -> 2026 | Z77: =MONTH(Table16[[#This Row],[Date]]) -> 5 | AA77: =MID(Table16[[#This Row],[Transaction_ID]],4,7) -> 1077 | AB77: =_xlfn.CONCAT(Table16[[#This Row],[Region]],"-",Table16[[#This Row],[Category]]) -> East-Home

Sheet sort
A1: Transaction_ID | B1: Date | C1: Region | D1: Sales_Channel | E1: Customer_Name | F1: Category | G1: Product | H1: Quantity | I1: Unit_Price_INR | J1: Discount_Rate | K1: Payment_Method | L1: Status | M1: Sales_Rep_ID | N1: Gross sales | O1: Discount_Amount | P1: Net_Sales | Q1: Transaction_month | R1: Transaction_Flag | S1: classification_netsales | T1: AND | U1: OR | V1: iferror | W1: T21 | X1: T212 | Y1: Year | Z1: Month | AA1: Column1 | AB1: Region_category
A2: TXN1015 | B2: 46045 | C2: West | D2: Wholesale | E2: Ocean Traders | F2: Electronics | G2: Smartphone | H2: 5 | I2: 28500 | J2: 0.06 | K2: Bank Transfer | L2: Completed | M2: EMP02 | N2: =Table14[[#This Row],[Quantity]]*Table14[[#This Row],[Unit_Price_INR]] -> 142500 | O2: =Table14[[#This Row],[Gross sales]]*Table14[[#This Row],[Discount_Rate]] -> 8550 | P2: =Table14[[#This Row],[Gross sales]]-Table14[[#This Row],[Discount_Amount]] -> 133950 | Q2: =TEXT(Table14[[#This Row],[Date]],"mmmm") -> January | R2: =IF(OR(Table14[[#This Row],[Status]]="Pending",Table14[[#This Row],[Status]]="Refunded"),"Review","OK") -> OK | S2: =IF(Table14[[#This Row],[Net_Sales]]>25000,"High",IF(Table14[[#This Row],[Net_Sales]]>10000,"Medium","Low")) -> High | T2: =AND(Table14[[#This Row],[Quantity]]>=5,Table14[[#This Row],[Discount_Rate]]>=10%) -> FALSE | U2: =OR(Table14[[#This Row],[Payment_Method]]="UPI",Table14[[#This Row],[Payment_Method]]="Cash") -> FALSE | V2: =IFERROR(Table14[[#This Row],[Net_Sales]]/Table14[[#This Row],[Quantity]],"ERROR") -> 26790 | W2: =PROPER(TRIM(Table14[[#This Row],[Customer_Name]])) -> Ocean Traders | X2: =PROPER(TRIM(Table14[[#This Row],[Region]])) -> West | Y2: =YEAR(Table14[[#This Row],[Date]]) -> 2026 | Z2: =MONTH(Table14[[#This Row],[Date]]) -> 1 | AA2: =MID(Table14[[#This Row],[Transaction_ID]],4,7) -> 1015 | AB2: =_xlfn.CONCAT(Table14[[#This Row],[Region]],"-",Table14[[#This Row],[Category]]) -> West-Electronics
A3: TXN1001 | B3: 46025 | C3: North | D3: Retail | E3: Asha Stores | F3: Electronics | G3: Laptop | H3: 2 | I3: 52000 | J3: 0.08 | K3: UPI | L3: Completed | M3: EMP01 | N3: =Table14[[#This Row],[Quantity]]*Table14[[#This Row],[Unit_Price_INR]] -> 104000 | O3: =Table14[[#This Row],[Gross sales]]*Table14[[#This Row],[Discount_Rate]] -> 8320 | P3: =Table14[[#This Row],[Gross sales]]-Table14[[#This Row],[Discount_Amount]] -> 95680 | Q3: =TEXT(Table14[[#This Row],[Date]],"mmmm") -> January | R3: =IF(OR(Table14[[#This Row],[Status]]="Pending",Table14[[#This Row],[Status]]="Refunded"),"Review","OK") -> OK | S3: =IF(Table14[[#This Row],[Net_Sales]]>25000,"High",IF(Table14[[#This Row],[Net_Sales]]>10000,"Medium","Low")) -> High | T3: =AND(Table14[[#This Row],[Quantity]]>=5,Table14[[#This Row],[Discount_Rate]]>=10%) -> FALSE | U3: =OR(Table14[[#This Row],[Payment_Method]]="UPI",Table14[[#This Row],[Payment_Method]]="Cash") -> TRUE | V3: =IFERROR(Table14[[#This Row],[Net_Sales]]/Table14[[#This Row],[Quantity]],"ERROR") -> 47840 | W3: =PROPER(TRIM(Table14[[#This Row],[Customer_Name]])) -> Asha Stores | X3: =PROPER(TRIM(Table14[[#This Row],[Region]])) -> North | Y3: =YEAR(Table14[[#This Row],[Date]]) -> 2026 | Z3: =MONTH(Table14[[#This Row],[Date]]) -> 1 | AA3: =MID(Table14[[#This Row],[Transaction_ID]],4,7) -> 1001 | AB3: =_xlfn.CONCAT(Table14[[#This Row],[Region]],"-",Table14[[#This Row],[Category]]) -> North-Electronics
A4: TXN1036 | B4: 46091 | C4: East | D4: Wholesale | E4: Juniper Distributors | F4: Electronics | G4: Projector | H4: 2 | I4: 46500 | J4: 0.08 | K4: Bank Transfer | L4: Completed | M4: EMP04 | N4: =Table14[[#This Row],[Quantity]]*Table14[[#This Row],[Unit_Price_INR]] -> 93000 | O4: =Table14[[#This Row],[Gross sales]]*Table14[[#This Row],[Discount_Rate]] -> 7440 | P4: =Table14[[#This Row],[Gross sales]]-Table14[[#This Row],[Discount_Amount]] -> 85560 | Q4: =TEXT(Table14[[#This Row],[Date]],"mmmm") -> March | R4: =IF(OR(Table14[[#This Row],[Status]]="Pending",Table14[[#This Row],[Status]]="Refunded"),"Review","OK") -> OK | S4: =IF(Table14[[#This Row],[Net_Sales]]>25000,"High",IF(Table14[[#This Row],[Net_Sales]]>10000,"Medium","Low")) -> High | T4: =AND(Table14[[#This Row],[Quantity]]>=5,Table14[[#This Row],[Discount_Rate]]>=10%) -> FALSE | U4: =OR(Table14[[#This Row],[Payment_Method]]="UPI",Table14[[#This Row],[Payment_Method]]="Cash") -> FALSE | V4: =IFERROR(Table14[[#This Row],[Net_Sales]]/Table14[[#This Row],[Quantity]],"ERROR") -> 42780 | W4: =PROPER(TRIM(Table14[[#This Row],[Customer_Name]])) -> Juniper Distributors | X4: =PROPER(TRIM(Table14[[#This Row],[Region]])) -> East | Y4: =YEAR(Table14[[#This Row],[Date]]) -> 2026 | Z4: =MONTH(Table14[[#This Row],[Date]]) -> 3 | AA4: =MID(Table14[[#This Row],[Transaction_ID]],4,7) -> 1036 | AB4: =_xlfn.CONCAT(Table14[[#This Row],[Region]],"-",Table14[[#This Row],[Category]]) -> East-Electronics
A5: TXN1045 | B5: 46110 | C5: North | D5: Wholesale | E5: Silverline Traders | F5: Electronics | G5: Camera | H5: 2 | I5: 42000 | J5: 0.07 | K5: Bank Transfer | L5: Completed | M5: EMP01 | N5: =Table14[[#This Row],[Quantity]]*Table14[[#This Row],[Unit_Price_INR]] -> 84000 | O5: =Table14[[#This Row],[Gross sales]]*Table14[[#This Row],[Discount_Rate]] -> 5880 | P5: =Table14[[#This Row],[Gross sales]]-Table14[[#This Row],[Discount_Amount]] -> 78120 | Q5: =TEXT(Table14[[#This Row],[Date]],"mmmm") -> March | R5: =IF(OR(Table14[[#This Row],[Status]]="Pending",Table14[[#This Row],[Status]]="Refunded"),"Review","OK") -> OK | S5: =IF(Table14[[#This Row],[Net_Sales]]>25000,"High",IF(Table14[[#This Row],[Net_Sales]]>10000,"Medium","Low")) -> High | T5: =AND(Table14[[#This Row],[Quantity]]>=5,Table14[[#This Row],[Discount_Rate]]>=10%) -> FALSE | U5: =OR(Table14[[#This Row],[Payment_Method]]="UPI",Table14[[#This Row],[Payment_Method]]="Cash") -> FALSE | V5: =IFERROR(Table14[[#This Row],[Net_Sales]]/Table14[[#This Row],[Quantity]],"ERROR") -> 39060 | W5: =PROPER(TRIM(Table14[[#This Row],[Customer_Name]])) -> Silverline Traders | X5: =PROPER(TRIM(Table14[[#This Row],[Region]])) -> North | Y5: =YEAR(Table14[[#This Row],[Date]]) -> 2026 | Z5: =MONTH(Table14[[#This Row],[Date]]) -> 3 | AA5: =MID(Table14[[#This Row],[Transaction_ID]],4,7) -> 1045 | AB5: =_xlfn.CONCAT(Table14[[#This Row],[Region]],"-",Table14[[#This Row],[Category]]) -> North-Electronics
A6: TXN1019 | B6: 46055 | C6: West | D6: Online | E6: Sunrise Shop | F6: Electronics | G6: Tablet | H6: 4 | I6: 22000 | J6: 0.12 | K6: Card | L6: Completed | M6: EMP02 | N6: =Table14[[#This Row],[Quantity]]*Table14[[#This Row],[Unit_Price_INR]] -> 88000 | O6: =Table14[[#This Row],[Gross sales]]*Table14[[#This Row],[Discount_Rate]] -> 10560 | P6: =Table14[[#This Row],[Gross sales]]-Table14[[#This Row],[Discount_Amount]] -> 77440 | Q6: =TEXT(Table14[[#This Row],[Date]],"mmmm") -> February | R6: =IF(OR(Table14[[#This Row],[Status]]="Pending",Table14[[#This Row],[Status]]="Refunded"),"Review","OK") -> OK | S6: =IF(Table14[[#This Row],[Net_Sales]]>25000,"High",IF(Table14[[#This Row],[Net_Sales]]>10000,"Medium","Low")) -> High | T6: =AND(Table14[[#This Row],[Quantity]]>=5,Table14[[#This Row],[Discount_Rate]]>=10%) -> FALSE | U6: =OR(Table14[[#This Row],[Payment_Method]]="UPI",Table14[[#This Row],[Payment_Method]]="Cash") -> FALSE | V6: =IFERROR(Table14[[#This Row],[Net_Sales]]/Table14[[#This Row],[Quantity]],"ERROR") -> 19360 | W6: =PROPER(TRIM(Table14[[#This Row],[Customer_Name]])) -> Sunrise Shop | X6: =PROPER(TRIM(Table14[[#This Row],[Region]])) -> West | Y6: =YEAR(Table14[[#This Row],[Date]]) -> 2026 | Z6: =MONTH(Table14[[#This Row],[Date]]) -> 2 | AA6: =MID(Table14[[#This Row],[Transaction_ID]],4,7) -> 1019 | AB6: =_xlfn.CONCAT(Table14[[#This Row],[Region]],"-",Table14[[#This Row],[Category]]) -> West-Electronics
A7: TXN1033 | B7: 46085 | C7: North | D7: Wholesale | E7: Grove Traders | F7: Home | G7: Refrigerator | H7: 2 | I7: 38500 | J7: 0.06 | K7: Bank Transfer | L7: Completed | M7: EMP01 | N7: =Table14[[#This Row],[Quantity]]*Table14[[#This Row],[Unit_Price_INR]] -> 77000 | O7: =Table14[[#This Row],[Gross sales]]*Table14[[#This Row],[Discount_Rate]] -> 4620 | P7: =Table14[[#This Row],[Gross sales]]-Table14[[#This Row],[Discount_Amount]] -> 72380 | Q7: =TEXT(Table14[[#This Row],[Date]],"mmmm") -> March | R7: =IF(OR(Table14[[#This Row],[Status]]="Pending",Table14[[#This Row],[Status]]="Refunded"),"Review","OK") -> OK | S7: =IF(Table14[[#This Row],[Net_Sales]]>25000,"High",IF(Table14[[#This Row],[Net_Sales]]>10000,"Medium","Low")) -> High | T7: =AND(Table14[[#This Row],[Quantity]]>=5,Table14[[#This Row],[Discount_Rate]]>=10%) -> FALSE | U7: =OR(Table14[[#This Row],[Payment_Method]]="UPI",Table14[[#This Row],[Payment_Method]]="Cash") -> FALSE | V7: =IFERROR(Table14[[#This Row],[Net_Sales]]/Table14[[#This Row],[Quantity]],"ERROR") -> 36190 | W7: =PROPER(TRIM(Table14[[#This Row],[Customer_Name]])) -> Grove Traders | X7: =PROPER(TRIM(Table14[[#This Row],[Region]])) -> North | Y7: =YEAR(Table14[[#This Row],[Date]]) -> 2026 | Z7: =MONTH(Table14[[#This Row],[Date]]) -> 3 | AA7: =MID(Table14[[#This Row],[Transaction_ID]],4,7) -> 1033 | AB7: =_xlfn.CONCAT(Table14[[#This Row],[Region]],"-",Table14[[#This Row],[Category]]) -> North-Home
A8: TXN1004 | B8: 46028 | C8: East | D8: Wholesale | E8: Delta Traders | F8: Office | G8: Printer | H8: 4 | I8: 18500 | J8: 0.1 | K8: Bank Transfer | L8: Completed | M8: EMP04 | N8: =Table14[[#This Row],[Quantity]]*Table14[[#This Row],[Unit_Price_INR]] -> 74000 | O8: =Table14[[#This Row],[Gross sales]]*Table14[[#This Row],[Discount_Rate]] -> 7400 | P8: =Table14[[#This Row],[Gross sales]]-Table14[[#This Row],[Discount_Amount]] -> 66600 | Q8: =TEXT(Table14[[#This Row],[Date]],"mmmm") -> January | R8: =IF(OR(Table14[[#This Row],[Status]]="Pending",Table14[[#This Row],[Status]]="Refunded"),"Review","OK") -> OK | S8: =IF(Table14[[#This Row],[Net_Sales]]>25000,"High",IF(Table14[[#This Row],[Net_Sales]]>10000,"Medium","Low")) -> High | T8: =AND(Table14[[#This Row],[Quantity]]>=5,Table14[[#This Row],[Discount_Rate]]>=10%) -> FALSE | U8: =OR(Table14[[#This Row],[Payment_Method]]="UPI",Table14[[#This Row],[Payment_Method]]="Cash") -> FALSE | V8: =IFERROR(Table14[[#This Row],[Net_Sales]]/Table14[[#This Row],[Quantity]],"ERROR") -> 16650 | W8: =PROPER(TRIM(Table14[[#This Row],[Customer_Name]])) -> Delta Traders | X8: =PROPER(TRIM(Table14[[#This Row],[Region]])) -> East | Y8: =YEAR(Table14[[#This Row],[Date]]) -> 2026 | Z8: =MONTH(Table14[[#This Row],[Date]]) -> 1 | AA8: =MID(Table14[[#This Row],[Transaction_ID]],4,7) -> 1004 | AB8: =_xlfn.CONCAT(Table14[[#This Row],[Region]],"-",Table14[[#This Row],[Category]]) -> East-Office
A9: TXN1048 | B9: 46118 | C9: East | D9: Wholesale | E9: Vista Traders | F9: Home | G9: Washing Machine | H9: 2 | I9: 31500 | J9: 0.08 | K9: Bank Transfer | L9: Completed | M9: EMP04 | N9: =Table14[[#This Row],[Quantity]]*Table14[[#This Row],[Unit_Price_INR]] -> 63000 | O9: =Table14[[#This Row],[Gross sales]]*Table14[[#This Row],[Discount_Rate]] -> 5040 | P9: =Table14[[#This Row],[Gross sales]]-Table14[[#This Row],[Discount_Amount]] -> 57960 | Q9: =TEXT(Table14[[#This Row],[Date]],"mmmm") -> April | R9: =IF(OR(Table14[[#This Row],[Status]]="Pending",Table14[[#This Row],[Status]]="Refunded"),"Review","OK") -> OK | S9: =IF(Table14[[#This Row],[Net_Sales]]>25000,"High",IF(Table14[[#This Row],[Net_Sales]]>10000,"Medium","Low")) -> High | T9: =AND(Table14[[#This Row],[Quantity]]>=5,Table14[[#This Row],[Discount_Rate]]>=10%) -> FALSE | U9: =OR(Table14[[#This Row],[Payment_Method]]="UPI",Table14[[#This Row],[Payment_Method]]="Cash") -> FALSE | V9: =IFERROR(Table14[[#This Row],[Net_Sales]]/Table14[[#This Row],[Quantity]],"ERROR") -> 28980 | W9: =PROPER(TRIM(Table14[[#This Row],[Customer_Name]])) -> Vista Traders | X9: =PROPER(TRIM(Table14[[#This Row],[Region]])) -> East | Y9: =YEAR(Table14[[#This Row],[Date]]) -> 2026 | Z9: =MONTH(Table14[[#This Row],[Date]]) -> 4 | AA9: =MID(Table14[[#This Row],[Transaction_ID]],4,7) -> 1048 | AB9: =_xlfn.CONCAT(Table14[[#This Row],[Region]],"-",Table14[[#This Row],[Category]]) -> East-Home
A10: TXN1011 | B10: 46037 | C10: West | D10: Retail | E10: Kingfisher Store | F10: Electronics | G10: Monitor | H10: 4 | I10: 11200 | J10: 0.08 | K10: Card | L10: Completed | M10: EMP02 | N10: =Table14[[#This Row],[Quantity]]*Table14[[#This Row],[Unit_Price_INR]] -> 44800 | O10: =Table14[[#This Row],[Gross sales]]*Table14[[#This Row],[Discount_Rate]] -> 3584 | P10: =Table14[[#This Row],[Gross sales]]-Table14[[#This Row],[Discount_Amount]] -> 41216 | Q10: =TEXT(Table14[[#This Row],[Date]],"mmmm") -> January | R10: =IF(OR(Table14[[#This Row],[Status]]="Pending",Table14[[#This Row],[Status]]="Refunded"),"Review","OK") -> OK | S10: =IF(Table14[[#This Row],[Net_Sales]]>25000,"High",IF(Table14[[#This Row],[Net_Sales]]>10000,"Medium","Low")) -> High | T10: =AND(Table14[[#This Row],[Quantity]]>=5,Table14[[#This Row],[Discount_Rate]]>=10%) -> FALSE | U10: =OR(Table14[[#This Row],[Payment_Method]]="UPI",Table14[[#This Row],[Payment_Method]]="Cash") -> FALSE | V10: =IFERROR(Table14[[#This Row],[Net_Sales]]/Table14[[#This Row],[Quantity]],"ERROR") -> 10304 | W10: =PROPER(TRIM(Table14[[#This Row],[Customer_Name]])) -> Kingfisher Store | X10: =PROPER(TRIM(Table14[[#This Row],[Region]])) -> West | Y10: =YEAR(Table14[[#This Row],[Date]]) -> 2026 | Z10: =MONTH(Table14[[#This Row],[Date]]) -> 1 | AA10: =MID(Table14[[#This Row],[Transaction_ID]],4,7) -> 1011 | AB10: =_xlfn.CONCAT(Table14[[#This Row],[Region]],"-",Table14[[#This Row],[Category]]) -> West-Electronics
A11: TXN1031 | B11: 46082 | C11: West | D11: Online | E11: Elm Retail | F11: Electronics | G11: Smartwatch | H11: 7 | I11: 6400 | J11: 0.1 | K11: Card | L11: Completed | M11: EMP02 | N11: =Table14[[#This Row],[Quantity]]*Table14[[#This Row],[Unit_Price_INR]] -> 44800 | O11: =Table14[[#This Row],[Gross sales]]*Table14[[#This Row],[Discount_Rate]] -> 4480 | P11: =Table14[[#This Row],[Gross sales]]-Table14[[#This Row],[Discount_Amount]] -> 40320 | Q11: =TEXT(Table14[[#This Row],[Date]],"mmmm") -> March | R11: =IF(OR(Table14[[#This Row],[Status]]="Pending",Table14[[#This Row],[Status]]="Refunded"),"Review","OK") -> OK | S11: =IF(Table14[[#This Row],[Net_Sales]]>25000,"High",IF(Table14[[#This Row],[Net_Sales]]>10000,"Medium","Low")) -> High | T11: =AND(Table14[[#This Row],[Quantity]]>=5,Table14[[#This Row],[Discount_Rate]]>=10%) -> TRUE | U11: =OR(Table14[[#This Row],[Payment_Method]]="UPI",Table14[[#This Row],[Payment_Method]]="Cash") -> FALSE | V11: =IFERROR(Table14[[#This Row],[Net_Sales]]/Table14[[#This Row],[Quantity]],"ERROR") -> 5760 | W11: =PROPER(TRIM(Table14[[#This Row],[Customer_Name]])) -> Elm Retail | X11: =PROPER(TRIM(Table14[[#This Row],[Region]])) -> West | Y11: =YEAR(Table14[[#This Row],[Date]]) -> 2026 | Z11: =MONTH(Table14[[#This Row],[Date]]) -> 3 | AA11: =MID(Table14[[#This Row],[Transaction_ID]],4,7) -> 1031 | AB11: =_xlfn.CONCAT(Table14[[#This Row],[Region]],"-",Table14[[#This Row],[Category]]) -> West-Electronics
A12: TXN1041 | B12: 46102 | C12: North | D12: Retail | E12: Olive Shop | F12: Electronics | G12: SSD Drive | H12: 9 | I12: 4200 | J12: 0.05 | K12: UPI | L12: Completed | M12: EMP01 | N12: =Table14[[#This Row],[Quantity]]*Table14[[#This Row],[Unit_Price_INR]] -> 37800 | O12: =Table14[[#This Row],[Gross sales]]*Table14[[#This Row],[Discount_Rate]] -> 1890 | P12: =Table14[[#This Row],[Gross sales]]-Table14[[#This Row],[Discount_Amount]] -> 35910 | Q12: =TEXT(Table14[[#This Row],[Date]],"mmmm") -> March | R12: =IF(OR(Table14[[#This Row],[Status]]="Pending",Table14[[#This Row],[Status]]="Refunded"),"Review","OK") -> OK | S12: =IF(Table14[[#This Row],[Net_Sales]]>25000,"High",IF(Table14[[#This Row],[Net_Sales]]>10000,"Medium","Low")) -> High | T12: =AND(Table14[[#This Row],[Quantity]]>=5,Table14[[#This Row],[Discount_Rate]]>=10%) -> FALSE | U12: =OR(Table14[[#This Row],[Payment_Method]]="UPI",Table14[[#This Row],[Payment_Method]]="Cash") -> TRUE | V12: =IFERROR(Table14[[#This Row],[Net_Sales]]/Table14[[#This Row],[Quantity]],"ERROR") -> 3990 | W12: =PROPER(TRIM(Table14[[#This Row],[Customer_Name]])) -> Olive Shop | X12: =PROPER(TRIM(Table14[[#This Row],[Region]])) -> North | Y12: =YEAR(Table14[[#This Row],[Date]]) -> 2026 | Z12: =MONTH(Table14[[#This Row],[Date]]) -> 3 | AA12: =MID(Table14[[#This Row],[Transaction_ID]],4,7) -> 1041 | AB12: =_xlfn.CONCAT(Table14[[#This Row],[Region]],"-",Table14[[#This Row],[Category]]) -> North-Electronics
A13: TXN1039 | B13: 46098 | C13: West | D13: Wholesale | E13: Maple Traders | F13: Office | G13: Filing Cabinet | H13: 3 | I13: 11200 | J13: 0.04 | K13: Bank Transfer | L13: Completed | M13: EMP02 | N13: =Table14[[#This Row],[Quantity]]*Table14[[#This Row],[Unit_Price_INR]] -> 33600 | O13: =Table14[[#This Row],[Gross sales]]*Table14[[#This Row],[Discount_Rate]] -> 1344 | P13: =Table14[[#This Row],[Gross sales]]-Table14[[#This Row],[Discount_Amount]] -> 32256 | Q13: =TEXT(Table14[[#This Row],[Date]],"mmmm") -> March | R13: =IF(OR(Table14[[#This Row],[Status]]="Pending",Table14[[#This Row],[Status]]="Refunded"),"Review","OK") -> OK | S13: =IF(Table14[[#This Row],[Net_Sales]]>25000,"High",IF(Table14[[#This Row],[Net_Sales]]>10000,"Medium","Low")) -> High | T13: =AND(Table14[[#This Row],[Quantity]]>=5,Table14[[#This Row],[Discount_Rate]]>=10%) -> FALSE | U13: =OR(Table14[[#This Row],[Payment_Method]]="UPI",Table14[[#This Row],[Payment_Method]]="Cash") -> FALSE | V13: =IFERROR(Table14[[#This Row],[Net_Sales]]/Table14[[#This Row],[Quantity]],"ERROR") -> 10752 | W13: =PROPER(TRIM(Table14[[#This Row],[Customer_Name]])) -> Maple Traders | X13: =PROPER(TRIM(Table14[[#This Row],[Region]])) -> West | Y13: =YEAR(Table14[[#This Row],[Date]]) -> 2026 | Z13: =MONTH(Table14[[#This Row],[Date]]) -> 3 | AA13: =MID(Table14[[#This Row],[Transaction_ID]],4,7) -> 1039 | AB13: =_xlfn.CONCAT(Table14[[#This Row],[Region]],"-",Table14[[#This Row],[Category]]) -> West-Office
... A77: TXN1065 | B77: 46149 | C77: East | D77: Online | E77: Lumen Shop | F77: Electronics | G77: USB-C Cable | H77: 0 | I77: 450 | J77: 0 | K77: Cash | L77: Cancelled | M77: EMP04 | N77: =Table14[[#This Row],[Quantity]]*Table14[[#This Row],[Unit_Price_INR]] -> 0 | O77: =Table14[[#This Row],[Gross sales]]*Table14[[#This Row],[Discount_Rate]] -> 0 | P77: =Table14[[#This Row],[Gross sales]]-Table14[[#This Row],[Discount_Amount]] -> 0 | Q77: =TEXT(Table14[[#This Row],[Date]],"mmmm") -> May | R77: =IF(OR(Table14[[#This Row],[Status]]="Pending",Table14[[#This Row],[Status]]="Refunded"),"Review","OK") -> OK | S77: =IF(Table14[[#This Row],[Net_Sales]]>25000,"High",IF(Table14[[#This Row],[Net_Sales]]>10000,"Medium","Low")) -> Low | T77: =AND(Table14[[#This Row],[Quantity]]>=5,Table14[[#This Row],[Discount_Rate]]>=10%) -> FALSE | U77: =OR(Table14[[#This Row],[Payment_Method]]="UPI",Table14[[#This Row],[Payment_Method]]="Cash") -> TRUE | V77: =IFERROR(Table14[[#This Row],[Net_Sales]]/Table14[[#This Row],[Quantity]],"ERROR") -> ERROR | W77: =PROPER(TRIM(Table14[[#This Row],[Customer_Name]])) -> Lumen Shop | X77: =PROPER(TRIM(Table14[[#This Row],[Region]])) -> East | Y77: =YEAR(Table14[[#This Row],[Date]]) -> 2026 | Z77: =MONTH(Table14[[#This Row],[Date]]) -> 5 | AA77: =MID(Table14[[#This Row],[Transaction_ID]],4,7) -> 1065 | AB77: =_xlfn.CONCAT(Table14[[#This Row],[Region]],"-",Table14[[#This Row],[Category]]) -> East-Electronics

Sheet Answers
A1: T05(Average) | B1: =AVERAGE(Transactions!I2:I77) -> 6655.7895
A2: T05(Total) | B2: =SUM(Transactions!H2:H77) -> 592
A3: T05(Total net sales) | B3: =SUM(Transactions!P2:P77) -> 1594263.8
A5: SECTIONC-Conditional calculations
A6: T11 | B6: =SUMIF(Transactions!C2:C77,"North",Transactions!P2:P77) -> 499870.9
A7: T12 | B7: =SUMIFS(Transactions!P2:P77,Transactions!C2:C77,"South",Transactions!L2:L77,"Completed") -> 128509.4
A8: T13 | B8: =COUNTIF(Transactions!L2:L77,"Pending") -> 5
A9: T14 | B9: =COUNTIFS(Transactions!D2:D77,"Online",Transactions!F2:F77,"Electronics") -> 7
A10: T15 | B10: =AVERAGEIF(Transactions!F2:F77,"Home",Transactions!I2:I77) -> 9755.625
A13: SECTION D-Lookup and references
A14: T17 | B14: EMP01 | C14: =VLOOKUP(B14,Lookup_table!A2:B6,2,FALSE) -> Lisa
A15: T18 | B15: TXN1001 | C15: =INDEX(Transactions!I2:I77,MATCH(Answers!B15,Transactions!A2:A77,0)) -> 52000
A16: T19 | B16: =MATCH("Smartphone",Transactions!G2:G77,0) -> 15
